<?xml version="1.0"?>

<robot name="tortoisebot">

  <!-- Base Link -->
  <link name="base_link">
    <visual>
      <geometry>
        <box size="0.47 0.47 0.1"/>
      </geometry>
      <material name="Red">
        <color rgba="1.0 0.0 0.0 1.0"/>
      </material>
    </visual>
    <collision>
      <geometry>
        <box size="0.47 0.47 0.1"/>
      </geometry>
    </collision>
    <inertial>
      <mass value="1.0"/>
      <inertia ixx="0.015" iyy="0.0375" izz="0.0375" ixy="0" ixz="0" iyz="0"/>
    </inertial>
  </link>


    <!-- Layer 1 -->
    <link name="layer_1">
        <visual>
            <geometry>
                <box size="0.4 0.47 0.06"/>
            </geometry>
            <material name="Red">
                <color rgba="1.0 0.0 0.0 1.0"/>
            </material>
        </visual>
    </link>

    <!-- Layer 2 -->
    <link name="layer_2">
        <visual>
            <geometry>
                <box size="0.47 0.47 0.04"/>
            </geometry>
            <material name="Red">
                <color rgba="1.0 0.0 0.0 1.0"/>
            </material>
        </visual>
    </link>

    <!-- Joints -->
    <joint name="layer_1_joint" type="fixed">
        <parent link="base_link"/>
        <child link="layer_1"/>
        <origin xyz="-0.035 0 0.08 "/>
    </joint>
    
    <joint name="layer_2_joint" type="fixed">
        <parent link="layer_1"/>
        <child link="layer_2"/>
        <origin xyz="0.035 0 0.05 "/>
    </joint>


  <!-- Front Left Caster -->
  <link name="front_left_caster">
    <visual>
      <geometry>
        <box size="0.000001 0.000001 0.000001"/>
      </geometry>
      <material name="silver"/>
    </visual>
    <collision>
      <geometry>
        <box size="0.000001 0.000001 0.000001"/>
      </geometry>
    </collision>
    <inertial>
      <mass value="0.1"/>
      <inertia ixx="0.00083" iyy="0.00083" izz="0.000167" ixy="0" ixz="0" iyz="0"/>
    </inertial>
  </link>

  <joint name="front_left_caster_joint" type="continuous">
    <axis xyz="0 0 1"/>
    <parent link="base_link"/>
    <child link="front_left_caster"/>
    <origin rpy="0 0 0" xyz="0.11 0.11 0"/>
  </joint>

  <link name="front_left_wheel">
    <visual>
      <geometry>
        <cylinder length="0.05" radius="0.035"/>
      </geometry>
      <material name="black">
        <color rgba="0 0 0 1"/>
      </material>
    </visual>
    <collision>
      <geometry>
        <cylinder length="0.05" radius="0.035"/>
      </geometry>
    </collision>
    <inertial>
      <mass value="0.1"/>
      <inertia ixx="5.1458e-5" iyy="5.1458e-5" izz="6.125e-5" ixy="0" ixz="0" iyz="0"/>
    </inertial>
  </link>

  <joint name="front_left_wheel_joint" type="continuous">
    <axis xyz="0 0 1"/>
    <parent link="front_left_caster"/>
    <child link="front_left_wheel"/>
    <origin rpy="-1.5708 0 0" xyz="0.05 0 -0.0475"/>
  </joint>

  <!-- Front Right Caster -->
  <link name="front_right_caster">
    <visual>
      <geometry>
        <box size="0.000001 0.000001 0.000001"/>
      </geometry>
      <material name="silver"/>
    </visual>
    <collision>
      <geometry>
        <box size="0.000001 0.000001 0.000001"/>
      </geometry>
    </collision>
    <inertial>
      <mass value="0.1"/>
      <inertia ixx="0.00083" iyy="0.00083" izz="0.000167" ixy="0" ixz="0" iyz="0"/>
    </inertial>
  </link>

  <joint name="front_right_caster_joint" type="continuous">
    <axis xyz="0 0 1"/>
    <parent link="base_link"/>
    <child link="front_right_caster"/>
    <origin rpy="0 0 0" xyz="0.11 -0.11 0"/>
  </joint>

  <link name="front_right_wheel">
    <visual>
      <geometry>
        <cylinder length="0.05" radius="0.035"/>
      </geometry>
      <material name="black">
        <color rgba="0 0 0 1"/>
      </material>
    </visual>
    <collision>
      <geometry>
        <cylinder length="0.05" radius="0.035"/>
      </geometry>
    </collision>
    <inertial>
      <mass value="0.1"/>
      <inertia ixx="5.1458e-5" iyy="5.1458e-5" izz="6.125e-5" ixy="0" ixz="0" iyz="0"/>
    </inertial>
  </link>

  <joint name="front_right_wheel_joint" type="continuous">
    <axis xyz="0 0 1"/>
    <parent link="front_right_caster"/>
    <child link="front_right_wheel"/>
    <origin rpy="-1.5708 0 0" xyz="0.05 0 -0.0475"/>
  </joint>

  <!-- Rear Left Caster -->
  <link name="rear_left_caster">
    <visual>
      <geometry>
        <box size="0.000001 0.000001 0.000001"/>
      </geometry>
      <material name="silver"/>
    </visual>
    <collision>
      <geometry>
        <box size="0.000001 0.000001 0.000001"/>
      </geometry>
    </collision>
    <inertial>
      <mass value="0.1"/>
      <inertia ixx="0.00083" iyy="0.00083" izz="0.000167" ixy="0" ixz="0" iyz="0"/>
    </inertial>
  </link>

  <joint name="rear_left_caster_joint" type="continuous">
    <axis xyz="0 0 1"/>
    <parent link="base_link"/>
    <child link="rear_left_caster"/>
    <origin rpy="0 0 0" xyz="-0.11 0.11 0"/>
  </joint>

  <link name="rear_left_wheel">
    <visual>
      <geometry>
        <cylinder length="0.05" radius="0.035"/>
      </geometry>
      <material name="black">
        <color rgba="0 0 0 1"/>
      </material>
    </visual>
    <collision>
      <geometry>
        <cylinder length="0.05" radius="0.035"/>
      </geometry>
    </collision>
    <inertial>
      <mass value="0.1"/>
      <inertia ixx="5.1458e-5" iyy="5.1458e-5" izz="6.125e-5" ixy="0" ixz="0" iyz="0"/>
    </inertial>
  </link>

  <joint name="rear_left_wheel_joint" type="continuous">
    <axis xyz="0 0 1"/>
    <parent link="rear_left_caster"/>
    <child link="rear_left_wheel"/>
    <origin rpy="-1.5708 0 0" xyz="0.05 0 -0.0475"/>
  </joint>

  <link name="rear_right_caster">
    <visual>
      <geometry>
        <box size="0.000001 0.000001 0.000001"/>
      </geometry>
      <material name="silver"/>
    </visual>
    <collision>
      <geometry>
        <box size="0.000001 0.000001 0.000001"/>
      </geometry>
    </collision>
    <inertial>
      <mass value="0.1"/>
      <inertia ixx="0.00083" iyy="0.00083" izz="0.000167" ixy="0" ixz="0" iyz="0"/>
    </inertial>
  </link>

  <joint name="rear_right_caster_joint" type="continuous">
    <axis xyz="0 0 1"/>
    <parent link="base_link"/>
    <child link="rear_right_caster"/>
    <origin rpy="0 0 0" xyz="-0.11 -0.11 0"/>
  </joint>

  <link name="rear_right_wheel">
    <visual>
      <geometry>
        <cylinder length="0.05" radius="0.035"/>
      </geometry>
      <material name="black">
        <color rgba="0 0 0 1"/>
      </material>
    </visual>
    <collision>
      <geometry>
        <cylinder length="0.05" radius="0.035"/>
      </geometry>
    </collision>
    <inertial>
      <mass value="0.1"/>
      <inertia ixx="5.1458e-5" iyy="5.1458e-5" izz="6.125e-5" ixy="0" ixz="0" iyz="0"/>
    </inertial>
  </link>

  <joint name="rear_right_wheel_joint" type="continuous">
    <axis xyz="0 0 1"/>
    <parent link="rear_right_caster"/>
    <child link="rear_right_wheel"/>
    <origin rpy="-1.5708 0 0" xyz="0.05 0 -0.0475"/>
  </joint>
  
	<link name="right_wheel">
		<visual>
			<geometry>
				<cylinder length="0.05" radius="0.08255"/>
			</geometry>
			<material name="black"/>
		</visual>
		<collision>
			<geometry>
				<cylinder length="0.05" radius="0.08255"/>
			</geometry>
		</collision>
		<inertial>
			<mass value="0.1"/>
			<inertia ixx="5.1458e-5" iyy="5.1458e-5" izz="6.125e-5"
			         ixy="0" ixz="0" iyz="0"/>
		</inertial>
	</link>
	
	<joint name="right_wheel_joint" type="continuous">
		<axis xyz="0 0 1"/>
		<parent link="base_link"/>
		<child link="right_wheel"/>
		<origin rpy="-1.5708 0 0" xyz="0 -0.155 0"/>
	</joint>
	
	<link name="left_wheel">
		<visual>
			<geometry>
				<cylinder length="0.05" radius="0.08255"/>
			</geometry>
			<material name="black"/>
		</visual>
		<collision>
			<geometry>
				<cylinder length="0.05" radius="0.08255"/>
			</geometry>
		</collision>
		<inertial>
			<mass value="0.1"/>
			<inertia ixx="5.1458e-5" iyy="5.1458e-5" izz="6.125e-5"
			         ixy="0" ixz="0" iyz="0"/>
		</inertial>
	</link>
	
	<joint name="left_wheel_joint" type="continuous">
		<axis xyz="0 0 1"/>
		<parent link="base_link"/>
		<child link="left_wheel"/>
		<origin rpy="-1.5708 0 0" xyz="0 0.155 0"/>
	</joint>

	<link name="lidar_link">
		<collision>
			<origin xyz="0 0 0" rpy="0 0 0"/>
			<geometry>
				<cylinder length="0.02" radius="0.09"/>
			</geometry>
		</collision>
		<visual>
			<origin xyz="0 0 0" rpy="0 0 0"/>
			<geometry>
				<cylinder length="0.02" radius="0.05"/>
			</geometry>
      <material name="Black">
        <color rgba="0.0 0.0 0.0 1.0"/>
      </material>

		</visual>
		<inertial>
			<mass value="1e-5"/>
			<origin xyz="0 0 0" rpy="0 0 0"/>
			<inertia ixx="1e-6" iyy="1e-6" izz="1e-6" ixy="0" ixz="0" iyz="0"/>
		</inertial>
	</link>
	
	<joint name="lidar_joint" type="fixed">
		<axis xyz="0.20 00 0"/>
		<origin xyz="0.20 0 0.2" rpy="0 0 0"/>
		<parent link="base_link"/>
		<child link="lidar_link"/>
	</joint>
	
	<gazebo>
    <plugin name="differential_drive_controller" filename="libgazebo_ros_diff_drive.so">
      <leftJoint>left_wheel_joint</leftJoint>
      <rightJoint>right_wheel_joint</rightJoint>
      <robotBaseFrame>base_link</robotBaseFrame>
      <wheelSeparation>0.25</wheelSeparation> <!-- Correct (0.125 * 2) -->
      <wheelDiameter>0.1651</wheelDiameter> <!-- Fixed: 2 * 0.08255 -->
      <publishWheelJointState>true</publishWheelJointState>
    </plugin>
		
		
		<plugin name="joint_state_publisher" filename="libgazebo_ros_joint_state_publisher.so">
			<jointName>front_left_caster_joint,front_left_wheel_joint,front_right_caster_joint,front_right_wheel_joint,rear_left_caster_joint,rear_left_wheel_joint,rear_right_caster_joint,rear_right_wheel_joint</jointName>
		</plugin>
	</gazebo>
	
	<gazebo reference="lidar_link">
		<sensor type="gpu_ray" name="hokuyo">
			<pose>0 0 0 0 0 0</pose>
			<visualize>false</visualize>
			<update_rate>100</update_rate>
			<ray>
				<scan>
					<horizontal>
						<samples>720</samples>
						<resolution>1</resolution>
						<min_angle>-3.141592</min_angle>
            <max_angle>3.141592</max_angle>
					</horizontal>
				</scan>
				<range>
					<min>0.10</min>
					<max>10.0</max>
					<resolution>0.01</resolution>
				</range>
			</ray>
			<plugin name="gpu_laser" filename="libgazebo_ros_gpu_laser.so">
				<topicName>/scan</topicName>
				<frameName>lidar_link</frameName>
			</plugin>
		</sensor>
	</gazebo>
	<gazebo reference="lidar_link">
		<sensor type="camera" name="camera1">
		<update_rate>30.0</update_rate>
		<camera name="head">
			<horizontal_fov>1.3962634</horizontal_fov>
			<image>
			<width>800</width>
			<height>800</height>
			<format>R8G8B8</format>
			</image>
			<clip>
			<near>0.02</near>
			<far>300</far>
			</clip>
			<noise>
			<type>gaussian</type>
			<!-- Noise is sampled independently per pixel on each frame.
				That pixel's noise value is added to each of its color
				channels, which at that point lie in the range [0,1]. -->
			<mean>0.0</mean>
			<stddev>0.007</stddev>
			</noise>
		</camera>
		<plugin name="camera_controller" filename="libgazebo_ros_camera.so">
			<alwaysOn>true</alwaysOn>
			<updateRate>0.0</updateRate>
			<cameraName>rrbot/camera1</cameraName>
			<imageTopicName>image_raw</imageTopicName>
			<cameraInfoTopicName>camera_info</cameraInfoTopicName>
			<frameName>camera_link</frameName>
			<hackBaseline>0.07</hackBaseline>
			<distortionK1>0.0</distortionK1>
			<distortionK2>0.0</distortionK2>
			<distortionK3>0.0</distortionK3>
			<distortionT1>0.0</distortionT1>
			<distortionT2>0.0</distortionT2>
		</plugin>
		</sensor>
	</gazebo>



</robot>